Workbook

Sheet NSA Enforcement Decisions
A1: Decision ID | B1: Case Name | C1: Provider / Claimant | D1: Payor / Defendant | E1: Court | F1: Court Level | G1: Circuit | H1: Docket No. | I1: Decision Date | J1: Court State | K1: Origin / Plan State | L1: Outcome | M1: Heat Map Code | N1: Decision Type | O1: NSA Private Right of Action? | P1: FAA §9 Confirmation? | Q1: Award Confirmed? | R1: Award Amount ($) | S1: Holding / Disposition Summary | T1: Precedential Weight | U1: Decision Status / Finality | V1: Appeal / Subsequent History | W1: Source URL | X1: Scope Category | Y1: Heat Map Include (Recommended) | Z1: Dashboard Caution / Notes | AA1: Verified Through
A2: NSA-001 | B2: GPS of New Jersey M.D., P.C. a/s/o *** v. Horizon Blue Cross Blue Shield of New Jersey | C2: GPS of New Jersey M.D., P.C. | D2: Horizon Blue Cross Blue Shield of New Jersey | E2: U.S. District Court, District of New Jersey | F2: Federal District | G2: 3d | H2: 2:22-cv-06614-KM-JBC | I2: 45177 | J2: NJ | K2: NJ | L2: Positive | M2: =IF(L2="Positive",1,IF(L2="Negative",-1,0)) | N2: Vacatur denied / award confirmed | O2: Not reached as provider-enforcement theory | P2: Confirmation granted in vacatur posture | Q2: Yes | S2: Denied provider's motion to vacate an NSA IDR award and granted Horizon's cross-motion to confirm the award. | T2: District court | U2: Final district ruling | V2: No direct provider-enforcement appeal tracked here | W2: https://law.justia.com/cases/federal/district-courts/new-jersey/njdce/2%3A2022cv06614/504421/21/ | X2: Context / vacatur-confirmation | Y2: No | Z2: Award favored payer; useful confirmation precedent but not a provider nonpayment enforcement suit. | AA2: 46295
A3: NSA-002 | B3: Worldwide Aircraft Services, Inc. d/b/a Jet ICU v. Worldwide Insurance Services, LLC d/b/a GeoBlue | C3: Jet ICU | D3: GeoBlue / Worldwide Insurance Services | E3: U.S. District Court, Middle District of Florida | F3: Federal District | G3: 11th | H3: 8:24-cv-00840 | I3: 45553 | J3: FL | K3: FL | L3: Positive | M3: =IF(L3="Positive",1,IF(L3="Negative",-1,0)) | N3: Petition to confirm granted | O3: Not central | P3: Court confirmed; §9 objection treated as waived | Q3: Yes | R3: 220204 | S3: Granted petition to confirm NSA IDR award and entered judgment for the provider. | T3: District court | U3: Final district ruling | V3: No subsequent appellate decision identified in public search | W3: https://docs.justia.com/cases/federal/district-courts/florida/flmdce/8%3A2024cv00840/426099/25 | X3: Direct enforcement | Y3: Yes | Z3: Positive result, but limited because the payer's challenge to FAA confirmation was treated as waived. | AA3: 46295
A4: NSA-003 | B4: FHMC LLC v. Blue Cross and Blue Shield of Arizona, Inc. | C4: FHMC LLC | D4: Blue Cross and Blue Shield of Arizona | E4: U.S. District Court, District of Arizona | F4: Federal District | G4: 9th | H4: 2:23-cv-00876 | I4: 45386 | J4: AZ | K4: AZ | L4: Negative | M4: =IF(L4="Positive",1,IF(L4="Negative",-1,0)) | N4: Enforcement claim dismissed | O4: No | P4: No | Q4: No | S4: Held the NSA does not create an implied private right of action to enforce an IDR award; detailed statutory scheme weighs against implication. | T4: District court | U4: Final district ruling | V4: No subsequent appellate decision identified in public search | W4: https://dockets.justia.com/docket/arizona/azdce/2%3A2023cv00876/1334867 | X4: Direct enforcement | Y4: Yes | Z4: Early negative enforcement decision frequently cited by later courts. | AA4: 46295
A5: NSA-004 | B5: Guardian Flight, L.L.C. v. Health Care Service Corp. | C5: Guardian Flight, L.L.C. | D5: Health Care Service Corp. | E5: U.S. District Court, Northern District of Texas | F5: Federal District | G5: 5th | H5: 3:23-cv-01861-B | I5: 45442 | J5: TX | K5: TX | L5: Negative | M5: =IF(L5="Positive",1,IF(L5="Negative",-1,0)) | N5: Enforcement suit dismissed | O5: No | P5: No | Q5: No | S5: Dismissed provider's suit seeking payment of NSA IDR awards, finding no private cause of action. | T5: District court | U5: Final district ruling | V5: Affirmed by Fifth Circuit on 2025-06-12 | W5: https://www.americanbar.org/groups/tort_trial_insurance_practice/resources/journal/2025-fall/recent-developments-health-insurance-life-insurance-disability-insurance-law/ | X5: Direct enforcement | Y5: Yes | Z5: Superseded in precedential significance by Fifth Circuit affirmance; retain as separate decision event. | AA5: 46295
A6: NSA-005 | B6: Guardian Flight, L.L.C. v. Health Care Service Corp. | C6: Guardian Flight, L.L.C. | D6: Health Care Service Corp. | E6: U.S. Court of Appeals for the Fifth Circuit | F6: Federal Appellate | G6: 5th | H6: 24-10561 | I6: 45820 | J6: LA | K6: TX | L6: Negative | M6: =IF(L6="Positive",1,IF(L6="Negative",-1,0)) | N6: District dismissal affirmed | O6: No | P6: No | Q6: No | S6: Held the NSA contains no express or implied private right of action to enforce or confirm IDR awards and treated enforcement as part of judicial review barred except for statutory vacatur grounds. | T6: Binding appellate precedent | U6: Final appellate ruling | V6: Certiorari denied by U.S. Supreme Court on 2026-01-12 | W6: https://www.americanbar.org/groups/health_law/news/2025/08/fifth-circuit-no-surprises-act-private-lawsuits-idr-awards/ | X6: Direct enforcement | Y6: Yes | Z6: For geographic heat map, Court State is LA (Fifth Circuit seat); Origin State is TX and may be preferable for state shading. | AA6: 46295
A7: NSA-006 | B7: Jeffrey Farkas, M.D., LLC v. Horizon Blue Cross Blue Shield of New Jersey | C7: Jeffrey Farkas, M.D., LLC | D7: Horizon Blue Cross Blue Shield of New Jersey | E7: U.S. District Court, Eastern District of New York | F7: Federal District | G7: 2d | H7: 1:25-cv-00054-HG | I7: 45840 | J7: NY | K7: NY | L7: Negative | M7: =IF(L7="Positive",1,IF(L7="Negative",-1,0)) | N7: Petition to confirm dismissed | O7: No | P7: No | Q7: No | S7: Dismissed action seeking confirmation of NSA IDR award; held neither the NSA nor FAA supplied the requested enforcement route. | T7: District court | U7: Final district ruling | V7: No subsequent appellate decision identified in public search | W7: https://caselaw.findlaw.com/court/us-dis-crt-ed-new-yor/117456844.html | X7: Direct enforcement | Y7: Yes | Z7: Negative district authority in Second Circuit before East Coast appellate ruling. | AA7: 46295
A8: NSA-007 | B8: East Coast Advanced Plastic Surgery, LLC v. Cigna Health and Life Insurance Co. | C8: East Coast Advanced Plastic Surgery, LLC | D8: Cigna Health and Life Insurance Co. / Connecticut General | E8: U.S. District Court, Southern District of New York | F8: Federal District | G8: 2d | H8: 1:25-cv-00255 | I8: 45883 | J8: NY | K8: NY | L8: Negative | M8: =IF(L8="Positive",1,IF(L8="Negative",-1,0)) | N8: Enforcement claims dismissed | O8: No | P8: No / not an independent basis | Q8: No | R8: 3000000 | S8: Dismissed provider claims seeking payment of more than $3 million in NSA IDR awards; held the NSA does not imply a private cause of action. | T8: District court | U8: Final district ruling | V8: Affirmed by Second Circuit on 2026-09-17 | W8: https://law.justia.com/cases/federal/district-courts/new-york/nysdce/1%3A2025cv00255/634810/49/ | X8: Direct enforcement | Y8: Yes | Z8: Superseded in precedential significance by Second Circuit affirmance; amount is described as more than $3 million, so recorded as approximate floor. | AA8: 46295
A9: NSA-008 | B9: Modern Orthopaedics of NJ v. Premera Blue Cross | C9: Modern Orthopaedics of NJ | D9: Premera Blue Cross | E9: U.S. District Court, District of New Jersey | F9: Federal District | G9: 3d | H9: 2:25-cv-01087 | I9: 45964 | J9: NJ | K9: NJ | L9: Negative | M9: =IF(L9="Positive",1,IF(L9="Negative",-1,0)) | N9: Confirmation/enforcement denied | O9: No | P9: No | Q9: No | S9: Held §9 of the FAA does not authorize confirmation of NSA IDR awards and the NSA does not create an implied enforcement cause of action. | T9: District court | U9: Final district ruling | V9: No subsequent appellate decision identified in public search | W9: https://law.justia.com/cases/federal/district-courts/new-jersey/njdce/2%3A2025cv01087/562531/29/ | X9: Direct enforcement | Y9: Yes | Z9: Leading D.N.J. decision cited by many subsequent cases. | AA9: 46295
A10: NSA-009 | B10: PHI Health, LLC v. Keating Auto Group Employee Benefit Plan Trust / Entrust, LLC | C10: PHI Health, LLC | D10: Keating Auto Group Employee Benefit Plan Trust / Entrust, LLC | E10: U.S. District Court, Southern District of Texas | F10: Federal District | G10: 5th | H10: 4:24-cv-02832 | I10: 46002 | J10: TX | K10: TX | L10: Negative | M10: =IF(L10="Positive",1,IF(L10="Negative",-1,0)) | N10: R&R adopted; enforcement dismissed | O10: No | P10: No | Q10: No | S10: Adopted recommendation rejecting private enforcement of NSA IDR awards, following Guardian Flight. | T10: District court | U10: Final district ruling | V10: No subsequent appellate decision identified in public search | W10: https://www.ded.uscourts.gov/sites/ded/files/opinions/24-1378.pdf | X10: Direct enforcement | Y10: Yes | Z10: Primary public link is a later court opinion citing the adopted Texas decision (2025 WL 3617339); verify PACER citation if displaying document link publicly. | AA10: 46295
A11: NSA-010 | B11: Freeman Pain Institute, P.A. v. Horizon Blue Cross Blue Shield of New Jersey | C11: Freeman Pain Institute, P.A. | D11: Horizon Blue Cross Blue Shield of New Jersey | E11: U.S. District Court, District of New Jersey | F11: Federal District | G11: 3d | H11: 2:25-cv-02507 | I11: 45985 | J11: NJ | K11: NJ | L11: Negative | M11: =IF(L11="Positive",1,IF(L11="Negative",-1,0)) | N11: Confirmation denied / complaint dismissed | O11: No | P11: No | Q11: No | S11: Held Congress did not create a private right of action to enforce NSA IDR awards; denied confirmation and dismissed. | T11: District court | U11: Final district ruling | V11: No subsequent appellate decision identified in public search | W11: https://law.justia.com/cases/federal/district-courts/new-jersey/njdce/2%3A2025cv02507/565759/20/ | X11: Direct enforcement | Y11: Yes | Z11: Part of a series of D.N.J. Horizon enforcement decisions. | AA11: 46295
A12: NSA-011 | B12: Northeast Neurosurgical Associates v. Horizon Blue Cross Blue Shield of New Jersey | C12: Northeast Neurosurgical Associates | D12: Horizon Blue Cross Blue Shield of New Jersey | E12: U.S. District Court, District of New Jersey | F12: Federal District | G12: 3d | H12: 2:25-cv-06288 | I12: 45986 | J12: NJ | K12: NJ | L12: Negative | M12: =IF(L12="Positive",1,IF(L12="Negative",-1,0)) | N12: Confirmation/enforcement denied | O12: No | P12: No | Q12: No | S12: Rejected private enforcement/confirmation of NSA IDR award. | T12: District court | U12: Final district ruling | V12: No subsequent appellate decision identified in public search | W12: https://law.justia.com/cases/federal/district-courts/new-jersey/njdce/2%3A2025cv06288/571096/17/ | X12: Direct enforcement | Y12: Yes | Z12: Part of a series of D.N.J. Horizon enforcement decisions. | AA12: 46295
A13: NSA-012 | B13: Garden State Pain Management v. Horizon Blue Cross Blue Shield of New Jersey | C13: Garden State Pain Management | D13: Horizon Blue Cross Blue Shield of New Jersey | E13: U.S. District Court, District of New Jersey | F13: Federal District | G13: 3d | H13: 2:25-cv-05679 | I13: 45992 | J13: NJ | K13: NJ | L13: Negative | M13: =IF(L13="Positive",1,IF(L13="Negative",-1,0)) | N13: Confirmation/enforcement denied | O13: No | P13: No | Q13: No | S13: Rejected private enforcement/confirmation of NSA IDR award. | T13: District court | U13: Final district ruling | V13: No subsequent appellate decision identified in public search | W13: https://law.justia.com/cases/federal/district-courts/new-jersey/njdce/2%3A2025cv05679/570355/21/ | X13: Direct enforcement | Y13: Yes | Z13: Part of a series of D.N.J. Horizon enforcement decisions. | AA13: 46295
A14: NSA-013 | B14: Complete Medical Wellness LLC v. Horizon Blue Cross Blue Shield of New Jersey | C14: Complete Medical Wellness LLC | D14: Horizon Blue Cross Blue Shield of New Jersey | E14: U.S. District Court, District of New Jersey | F14: Federal District | G14: 3d | H14: 2:25-cv-04177 | I14: 45992 | J14: NJ | K14: NJ | L14: Negative | M14: =IF(L14="Positive",1,IF(L14="Negative",-1,0)) | N14: Confirmation/enforcement denied | O14: No | P14: No | Q14: No | S14: Rejected private enforcement/confirmation of NSA IDR award. | T14: District court | U14: Final district ruling | V14: No subsequent appellate decision identified in public search | W14: https://law.justia.com/cases/federal/district-courts/new-jersey/njdce/2%3A2025cv04177/568468/17/ | X14: Direct enforcement | Y14: Yes | Z14: Part of a series of D.N.J. Horizon enforcement decisions. | AA14: 46295
A15: NSA-014 | B15: Tamagnini v. Horizon Blue Cross Blue Shield of New Jersey | C15: Tamagnini | D15: Horizon Blue Cross Blue Shield of New Jersey | E15: U.S. District Court, District of New Jersey | F15: Federal District | G15: 3d | H15: 2:25-cv-02022 | I15: 45993 | J15: NJ | K15: NJ | L15: Negative | M15: =IF(L15="Positive",1,IF(L15="Negative",-1,0)) | N15: Confirmation/enforcement denied | O15: No | P15: No | Q15: No | S15: Rejected private enforcement/confirmation of NSA IDR award. | T15: District court | U15: Final district ruling | V15: No subsequent appellate decision identified in public search | W15: https://law.justia.com/cases/federal/district-courts/new-jersey/njdce/2%3A2025cv02022/564436/16/ | X15: Direct enforcement | Y15: Yes | Z15: Part of a series of D.N.J. Horizon enforcement decisions. | AA15: 46295
A16: NSA-015 | B16: Douglas Spiel, M.D., P.A. v. Horizon Blue Cross Blue Shield of New Jersey | C16: Douglas Spiel, M.D., P.A. | D16: Horizon Blue Cross Blue Shield of New Jersey | E16: U.S. District Court, District of New Jersey | F16: Federal District | G16: 3d | H16: 2:25-cv-14769 | I16: 45993 | J16: NJ | K16: NJ | L16: Negative | M16: =IF(L16="Positive",1,IF(L16="Negative",-1,0)) | N16: Confirmation/enforcement denied | O16: No | P16: No | Q16: No | S16: Rejected private enforcement/confirmation of NSA IDR award. | T16: District court | U16: Final district ruling | V16: No subsequent appellate decision identified in public search | W16: https://law.justia.com/cases/federal/district-courts/new-jersey/njdce/2%3A2025cv14769/581737/14/ | X16: Direct enforcement | Y16: Yes | Z16: Part of a series of D.N.J. Horizon enforcement decisions. | AA16: 46295
A17: NSA-016 | B17: Interventional Pain Management v. Horizon Blue Cross Blue Shield of New Jersey | C17: Interventional Pain Management | D17: Horizon Blue Cross Blue Shield of New Jersey | E17: U.S. District Court, District of New Jersey | F17: Federal District | G17: 3d | H17: 2:25-cv-12032 | I17: 45994 | J17: NJ | K17: NJ | L17: Negative | M17: =IF(L17="Positive",1,IF(L17="Negative",-1,0)) | N17: Confirmation/enforcement denied | O17: No | P17: No | Q17: No | S17: Rejected private enforcement/confirmation of NSA IDR award. | T17: District court | U17: Final district ruling | V17: No subsequent appellate decision identified in public search | W17: https://law.justia.com/cases/federal/district-courts/new-jersey/njdce/2%3A2025cv12032/577453/18/ | X17: Direct enforcement | Y17: Yes | Z17: Part of a series of D.N.J. Horizon enforcement decisions. | AA17: 46295
A18: NSA-017 | B18: T.V. Seshan, M.D., P.C. v. Blue Cross Blue Shield Association et al. | C18: T.V. Seshan, M.D., P.C. | D18: Blue Cross Blue Shield entities | E18: U.S. District Court, Southern District of New York | F18: Federal District | G18: 2d | H18: 25 Civ. 499 / 1255 / 1264 / 2049 | I18: 45996 | J18: NY | K18: NY | L18: Negative | M18: =IF(L18="Positive",1,IF(L18="Negative",-1,0)) | N18: Motions to dismiss granted / confirmation denied | O18: No | P18: No | Q18: No | S18: Granted dismissal and denied motions to confirm NSA IDR awards in consolidated matters. | T18: District court | U18: Final district ruling | V18: No subsequent appellate decision identified in public search | W18: https://law.justia.com/cases/federal/district-courts/new-york/nysdce/7%3A2025cv00499/635237/49/ | X18: Direct enforcement | Y18: Yes | Z18: Consolidated disposition; analyst may count as one decision event rather than four cases. | AA18: 46295
A19: NSA-018 | B19: Mitchell F. Reiter, M.D., P.C. v. Horizon Blue Cross Blue Shield of New Jersey | C19: Mitchell F. Reiter, M.D., P.C. | D19: Horizon Blue Cross Blue Shield of New Jersey | E19: U.S. District Court, District of New Jersey | F19: Federal District | G19: 3d | H19: 2:25-cv-12526 | I19: 45999 | J19: NJ | K19: NJ | L19: Negative | M19: =IF(L19="Positive",1,IF(L19="Negative",-1,0)) | N19: Dismissal granted / confirmation denied | O19: No | P19: No | Q19: No | S19: Granted payer motion to dismiss and denied provider cross-motion to confirm the NSA IDR award. | T19: District court | U19: Final district ruling | V19: No subsequent appellate decision identified in public search | W19: https://cases.justia.com/federal/district-courts/new-jersey/njdce/2%3A2025cv12526/578331/13/0.pdf | X19: Direct enforcement | Y19: Yes | Z19: Part of a series of D.N.J. Horizon enforcement decisions. | AA19: 46295
A20: NSA-019 | B20: Worldwide Aircraft Services, Inc. d/b/a Jet ICU v. Freedom Life Insurance Co. | C20: Jet ICU | D20: Freedom Life Insurance Co. | E20: U.S. District Court, Middle District of Florida | F20: Federal District | G20: 11th | H20: 8:25-cv-01158 | I20: 46002 | J20: FL | K20: FL | L20: Negative | M20: =IF(L20="Positive",1,IF(L20="Negative",-1,0)) | N20: Petition dismissed | O20: No / no federal cause | P20: No independent jurisdiction | Q20: No | S20: Dismissed provider's confirmation action for lack of subject-matter jurisdiction. | T20: District court | U20: Final district ruling | V20: Dismissed without prejudice. Provider appealed to the Eleventh Circuit on 1/5/2026; district case stayed (see Pending Cases). | W20: https://law.justia.com/cases/federal/district-courts/florida/flmdce/8%3A2025cv01158/441542/50/ | X20: Direct enforcement | Y20: Yes | Z20: Same provider had a positive 2024 GeoBlue confirmation decision, illustrating jurisdiction/posture differences. | AA20: 46311
A21: NSA-020 | B21: North Jersey Neurosurgical Associates, P.A. v. Horizon Blue Cross Blue Shield of New Jersey | C21: North Jersey Neurosurgical Associates, P.A. | D21: Horizon Blue Cross Blue Shield of New Jersey | E21: U.S. District Court, District of New Jersey | F21: Federal District | G21: 3d | H21: 2:25-cv-12593 | I21: 46009 | J21: NJ | K21: NJ | L21: Negative | M21: =IF(L21="Positive",1,IF(L21="Negative",-1,0)) | N21: Enforcement action dismissed | O21: No | P21: No | Q21: No | R21: 299232.67 | S21: Dismissed action seeking enforcement of NSA IDR award, following Modern Orthopaedics. | T21: District court | U21: Final district ruling | V21: Dismissed with prejudice | W21: https://law.justia.com/cases/federal/district-courts/new-jersey/njdce/2%3A2025cv12593/578403/18/ | X21: Direct enforcement | Y21: Yes | Z21: Award amount reflected in public decision. | AA21: 46295
A22: NSA-021 | B22: Comprehensive OBGYN, P.A. v. Horizon Blue Cross Blue Shield of New Jersey | C22: Comprehensive OBGYN, P.A. | D22: Horizon Blue Cross Blue Shield of New Jersey | E22: U.S. District Court, District of New Jersey | F22: Federal District | G22: 3d | H22: 2:25-cv-12682 | I22: 46009 | J22: NJ | K22: NJ | L22: Negative | M22: =IF(L22="Positive",1,IF(L22="Negative",-1,0)) | N22: Enforcement action dismissed | O22: No | P22: No | Q22: No | R22: 17127.88 | S22: Dismissed action seeking enforcement of NSA IDR award. | T22: District court | U22: Final district ruling | V22: No subsequent appellate decision identified in public search | W22: https://law.justia.com/cases/federal/district-courts/new-jersey/njdce/2%3A2025cv12682/578514/20/ | X22: Direct enforcement | Y22: Yes | Z22: Award amount reflected in public decision. | AA22: 46295
A23: NSA-022 | B23: Neuromon Professionals LLC v. Aetna Life Insurance Co. | C23: Neuromon Professionals LLC | D23: Aetna Life Insurance Co. | E23: U.S. District Court, District of New Jersey | F23: Federal District | G23: 3d | H23: 2:25-cv-01701 | I23: 46009 | J23: NJ | K23: NJ | L23: Negative | M23: =IF(L23="Positive",1,IF(L23="Negative",-1,0)) | N23: Enforcement action dismissed | O23: No | P23: No | Q23: No | R23: 22900 | S23: Dismissed action seeking enforcement of two NSA IDR awards. | T23: District court | U23: Final district ruling | V23: No subsequent appellate decision identified in public search | W23: https://law.justia.com/cases/federal/district-courts/new-jersey/njdce/2%3A2025cv01701/563886/20/ | X23: Direct enforcement | Y23: Yes | Z23: Amount combines two public award amounts ($11,200 + $11,700). | AA23: 46295
A24: NSA-023 | B24: GuardION Medical LLC v. MedCost Benefit Services LLC | C24: GuardION Medical LLC | D24: MedCost Benefit Services LLC | E24: U.S. District Court, Middle District of Georgia | F24: Federal District | G24: 11th | H24: 5:25-cv-00223 | I24: 46049 | J24: GA | K24: GA | L24: Negative | M24: =IF(L24="Positive",1,IF(L24="Negative",-1,0)) | N24: Petition dismissed / confirmation denied | O24: No | P24: No | Q24: No | R24: 15400 | S24: Held no implied NSA cause of action to enforce IDR awards and dismissed petition for lack of subject-matter jurisdiction. | T24: District court | U24: Final district ruling | V24: No subsequent appellate decision identified in public search | W24: https://docs.justia.com/cases/federal/district-courts/georgia/gamdce/5%3A2025cv00223/137486/17 | X24: Direct enforcement | Y24: Yes | Z24: Public opinion describes total award as approximately $15,400. | AA24: 46295
A25: NSA-024 | B25: Worldwide Aircraft Services, Inc. d/b/a Jet ICU v. Aetna Life Insurance Co. | C25: Jet ICU | D25: Aetna Life Insurance Co. | E25: U.S. District Court, Middle District of Florida | F25: Federal District | G25: 11th | H25: 8:25-cv-02231 | I25: 46057 | J25: FL | K25: FL | L25: Negative | M25: =IF(L25="Positive",1,IF(L25="Negative",-1,0)) | N25: Petition dismissed | O25: No | P25: No | Q25: No | R25: 93594 | S25: Granted Aetna's motion to dismiss provider's petition to confirm NSA IDR award. | T25: District court | U25: Final district ruling | V25: Dismissed with prejudice | W25: https://docs.justia.com/cases/federal/district-courts/florida/flmdce/8%3A2025cv02231/446265/23 | X25: Direct enforcement | Y25: Yes | Z25: Contrasts with Jet ICU's 2024 GeoBlue confirmation case. | AA25: 46295
A26: NSA-025 | B26: SpecialtyCare, Inc. v. MedCost, LLC | C26: SpecialtyCare, Inc. et al. | D26: MedCost, LLC | E26: Delaware Court of Chancery | F26: State Trial | G26: N/A | H26: C.A. No. 2025-0011-DH | I26: 46069 | J26: DE | K26: DE | L26: Negative | M26: =IF(L26="Positive",1,IF(L26="Negative",-1,0)) | N26: State-law enforcement claims dismissed | O26: No | P26: No | Q26: No | S26: Held the NSA does not imply a private enforcement right and dismissed claims seeking payment of IDR awards. | T26: State trial court | U26: Final state trial ruling | V26: No subsequent appellate decision identified in public search | W26: https://law.justia.com/cases/delaware/court-of-chancery/2026/c-a-no-2025-0011-dh.html | X26: Direct enforcement | Y26: Yes | Z26: Important state-court decision; not a federal district ruling. | AA26: 46295
A27: NSA-026 | B27: SpecialtyCare, Inc. et al. v. CIGNA Healthcare, Inc. | C27: SpecialtyCare, Inc. / Remote Neuromonitoring Physicians / Sentient Physicians | D27: CIGNA Healthcare, Inc. | E27: U.S. District Court, District of Delaware | F27: Federal District | G27: 3d | H27: 1:24-cv-01378 | I27: 46073 | J27: DE | K27: DE | L27: Negative | M27: =IF(L27="Positive",1,IF(L27="Negative",-1,0)) | N27: Report & Recommendation recommending dismissal | O27: No | P27: No | Q27: No | S27: R&R concluded neither the NSA nor FAA provides a private enforcement route. | T27: Magistrate R&R | U27: Final district ruling (R&R adopted 3/26/2026; Counts I-III dismissed with prejudice) | V27: Third Circuit appeal later docketed as No. 26-1768 after district disposition | W27: https://docs.justia.com/cases/federal/district-courts/delaware/dedce/1%3A2024cv01378/87654/26 | X27: Direct enforcement - nonfinal | Y27: No | Z27: Do not heat-map this R&R as a final decision; track final district disposition separately when verified. | AA27: 46311
A28: NSA-027 | B28: SpecialtyCare, Inc. et al. v. UMR, Inc. | C28: SpecialtyCare, Inc. / Remote Neuromonitoring Physicians / Sentient Physicians | D28: UMR, Inc. | E28: U.S. District Court, District of Delaware | F28: Federal District | G28: 3d | H28: 1:24-cv-01396 | I28: 46073 | J28: DE | K28: DE | L28: Negative | M28: =IF(L28="Positive",1,IF(L28="Negative",-1,0)) | N28: Report & Recommendation recommending dismissal | O28: No | P28: No | Q28: No | S28: R&R concluded neither the NSA nor FAA provides a private enforcement route. | T28: Magistrate R&R | U28: Final district ruling (R&R adopted 3/26/2026; Counts I-III dismissed with prejudice) | V28: Third Circuit appeal later docketed as No. 26-1769 after district disposition | W28: https://docs.justia.com/cases/federal/district-courts/delaware/dedce/1%3A2024cv01396/87709/24 | X28: Direct enforcement - nonfinal | Y28: No | Z28: Do not heat-map this R&R as a final decision; track final district disposition separately when verified. | AA28: 46311
A29: NSA-028 | B29: SpecialtyCare, Inc. et al. v. Meritain Health, Inc. | C29: SpecialtyCare, Inc. / Remote Neuromonitoring Physicians / Sentient Physicians | D29: Meritain Health, Inc. | E29: U.S. District Court, District of Delaware | F29: Federal District | G29: 3d | H29: 1:25-cv-00198 | I29: 46098 | J29: DE | K29: DE | L29: Negative | M29: =IF(L29="Positive",1,IF(L29="Negative",-1,0)) | N29: R&R adopted / complaint dismissed | O29: No | P29: No | Q29: No | S29: Adopted R&R and held the NSA does not create a private right of action; state-law theories cannot circumvent that omission. | T29: District court | U29: Final district ruling | V29: No subsequent appellate decision identified in public search | W29: https://docs.justia.com/cases/federal/district-courts/delaware/dedce/1%3A2025cv00198/88260/42 | X29: Direct enforcement | Y29: Yes | Z29: Final decision; replaces the 2026-02-09 R&R for heat-map purposes. | AA29: 46295
A30: NSA-029 | B30: PHI Health, LLC v. Optimum Choice, Inc. | C30: PHI Health, LLC | D30: Optimum Choice, Inc. | E30: U.S. District Court, District of Maryland | F30: Federal District | G30: 4th | H30: 1:25-cv-02320-ABA | I30: 46108 | J30: MD | K30: MD | L30: Positive | M30: =IF(L30="Positive",1,IF(L30="Negative",-1,0)) | N30: Motion to dismiss denied | O30: Yes | P30: Alternative theory discussed | Q30: Not yet at this stage | S30: Held Congress intended a judicial remedy for nonpayment of binding IDR awards and allowed PHI's enforcement cause of action to proceed. | T30: District court | U30: Interlocutory merits ruling | V30: Case continued after denial; monitor for final judgment/appeal | W30: https://law.justia.com/cases/federal/district-courts/maryland/mddce/1%3A2025cv02320/586626/44/ | X30: Direct enforcement | Y30: Yes | Z30: Positive on availability of enforcement action, but not itself a final confirmation judgment. | AA30: 46295
A31: NSA-030 | B31: NeuroShield Network SE, LLC v. Phoenix Administrators, LLC d/b/a Performance Health | C31: NeuroShield Network SE, LLC | D31: Phoenix Administrators, LLC / Performance Health | E31: U.S. District Court, Northern District of Ohio | F31: Federal District | G31: 6th | H31: 1:25-cv-01277 | I31: 46111 | J31: OH | K31: OH | L31: Negative | M31: =IF(L31="Positive",1,IF(L31="Negative",-1,0)) | N31: Petition dismissed | O31: No | P31: No | Q31: No | R31: 15400 | S31: Held the NSA confers no implied cause of action permitting enforcement of IDR awards and dismissed for lack of subject-matter jurisdiction. | T31: District court | U31: Final district ruling | V31: No subsequent appellate decision identified in public search | W31: https://law.justia.com/cases/federal/district-courts/ohio/ohndce/1%3A2025cv01277/318516/17/ | X31: Direct enforcement | Y31: Yes | Z31: Unpaid amount requested was about $15,048.31; total award approximately $15,400. | AA31: 46295
A32: NSA-031 | B32: T.V. Seshan, M.D., P.C. v. Aetna, Inc. | C32: T.V. Seshan, M.D., P.C. | D32: Aetna, Inc. | E32: U.S. District Court, Southern District of New York | F32: Federal District | G32: 2d | H32: 7:25-cv-02938 | I32: 46111 | J32: NY | K32: NY | L32: Negative | M32: =IF(L32="Positive",1,IF(L32="Negative",-1,0)) | N32: Petition to confirm dismissed | O32: No | P32: No | Q32: No | S32: Dismissed petition to confirm NSA IDR award. | T32: District court | U32: Final district ruling | V32: No subsequent appellate decision identified in public search | W32: https://law.justia.com/cases/federal/district-courts/new-york/nysdce/7%3A2025cv02938/640257/18/ | X32: Direct enforcement | Y32: Yes | Z32: Consistent with later Second Circuit East Coast ruling. | AA32: 46295
A33: NSA-032 | B33: Jeffrey Farkas, M.D., LLC v. 1199SEIU National Benefit Fund | C33: Jeffrey Farkas, M.D., LLC | D33: 1199SEIU National Benefit Fund | E33: U.S. District Court, Eastern District of New York | F33: Federal District | G33: 2d | H33: 1:25-cv-00057 | I33: 46113 | J33: NY | K33: NY | L33: Negative | M33: =IF(L33="Positive",1,IF(L33="Negative",-1,0)) | N33: Dismissal granted / confirmation denied | O33: No | P33: No | Q33: No | S33: Granted motion to dismiss and denied cross-motion to confirm NSA IDR award. | T33: District court | U33: Final district ruling | V33: No subsequent appellate decision identified in public search | W33: https://law.justia.com/cases/federal/district-courts/new-york/nyedce/1%3A2025cv00057/525792/33/ | X33: Direct enforcement | Y33: Yes | Z33: Consistent with later Second Circuit East Coast ruling. | AA33: 46295
A34: NSA-033 | B34: Advanced Vascular Associates v. Horizon Blue Cross Blue Shield of New Jersey | C34: Advanced Vascular Associates | D34: Horizon Blue Cross Blue Shield of New Jersey | E34: U.S. District Court, Eastern District of Pennsylvania | F34: Federal District | G34: 3d | H34: 2:25-cv-05068-JDW | I34: 46119 | J34: PA | K34: PA | L34: Negative | M34: =IF(L34="Positive",1,IF(L34="Negative",-1,0)) | N34: Judgment on pleadings / confirmation denied | O34: No | P34: No | Q34: No | S34: Held courts are not authorized to confirm or enforce NSA IDR determinations under the FAA and the NSA creates no private cause of action. | T34: District court | U34: Final district ruling | V34: No subsequent appellate decision identified in public search | W34: https://docs.justia.com/cases/federal/district-courts/pennsylvania/paedce/2%3A2025cv05068/643142/26 | X34: Direct enforcement | Y34: Yes | Z34: Clear negative merits decision on both NSA and FAA theories. | AA34: 46295
A35: NSA-034 | B35: Agag v. Cigna Health and Life Insurance Co. | C35: Agag | D35: Cigna Health and Life Insurance Co. | E35: U.S. District Court, District of Connecticut | F35: Federal District | G35: 2d | H35: 3:25-cv-00498-SRU | I35: 46127 | J35: CT | K35: CT | L35: Positive | M35: =IF(L35="Positive",1,IF(L35="Negative",-1,0)) | N35: Cross-motion to confirm granted | O35: Limited: no NSA damages action | P35: No under FAA; confirmation allowed under NSA summary proceeding | Q35: Yes | R35: 142567.99 | S35: Held federal-question jurisdiction existed and a provider could seek confirmation through a summary NSA proceeding; granted confirmation while rejecting FAA confirmation and NSA damages theories. | T35: District court | U35: Final confirmation judgment | V35: Second Circuit's 2026-09-17 East Coast decision creates controlling contrary authority on implied private enforcement; monitor Agag subsequent history | W35: https://www.govinfo.gov/content/pkg/USCOURTS-ctd-3_25-cv-00498/pdf/USCOURTS-ctd-3_25-cv-00498-0.pdf | X35: Direct enforcement | Y35: Yes | Z35: Positive confirmation result, but theory is narrower than an implied damages cause and may be affected by later Second Circuit authority. | AA35: 46295
A36: NSA-035 | B36: Guardian Flight LLC et al. v. Aetna Health Inc. et al. | C36: Guardian Flight LLC et al. | D36: Aetna Health / Aetna Life / Cigna entities | E36: U.S. District Court, District of Connecticut | F36: Federal District | G36: 2d | H36: 3:24-cv-00680 | I36: 45791 | J36: CT | K36: CT | L36: Positive | M36: =IF(L36="Positive",1,IF(L36="Negative",-1,0)) | N36: Motion to dismiss denied | O36: Yes | P36: Not required at pleading stage | Q36: No final confirmation at this stage | S36: Held the NSA supports an implied private cause of action to enforce IDR awards and allowed enforcement claims to proceed. | T36: District court | U36: Interlocutory merits ruling | V36: Later Second Circuit East Coast decision on 2026-09-17 is controlling contrary appellate authority in the circuit. 6/16/2026: court granted the providers' motion to dismiss Aetna's counterclaims; the case continues. | W36: https://app.midpage.ai/document/guardian-flight-llc-v-aetna-11050925 | X36: Direct enforcement | Y36: Yes | Z36: Positive district ruling now in tension with binding Second Circuit authority. | AA36: 46311
A37: NSA-036 | B37: SpecialtyCare, Inc. et al. v. CareFirst of Maryland, Inc. | C37: SpecialtyCare, Inc. et al. | D37: CareFirst of Maryland, Inc. | E37: U.S. District Court, District of Maryland | F37: Federal District | G37: 4th | H37: 1:25-cv-00130-ABA | I37: 46182 | J37: MD | K37: MD | L37: Positive | M37: =IF(L37="Positive",1,IF(L37="Negative",-1,0)) | N37: Motion to dismiss denied as to NSA enforcement count | O37: Yes | P37: Not central | Q37: Not yet at this stage | S37: Following PHI Health v. Optimum Choice, denied dismissal of the NSA enforcement count and allowed the provider's claim to proceed. | T37: District court | U37: Interlocutory merits ruling | V37: Case continued; monitor final disposition/appeal | W37: https://www2.mdd.uscourts.gov/Opinions/Opinions/2026-06-09%20SpecialtyCare%20granting%20in%20part%20MTD%20%2825-130%29.pdf | X37: Direct enforcement | Y37: Yes | Z37: Positive Fourth Circuit district authority; not a final confirmation judgment. | AA37: 46295
A38: NSA-037 | B38: SpecialtyCare, Inc. et al. v. Health Care Service Corp. d/b/a BCBS Illinois | C38: SpecialtyCare, Inc. / Remote Neuromonitoring Physicians / Sentient Physicians | D38: Health Care Service Corp. d/b/a BCBS Illinois | E38: U.S. District Court, Northern District of Illinois | F38: Federal District | G38: 7th | H38: 1:24-cv-12935 | I38: 46175 | J38: IL | K38: IL | L38: Negative | M38: =IF(L38="Positive",1,IF(L38="Negative",-1,0)) | N38: Federal claims dismissed | O38: No | P38: No | Q38: No | S38: Dismissed federal NSA/FAA enforcement theories; state claims dismissed without prejudice. | T38: District court | U38: Final district ruling | V38: Appeal docketed in Seventh Circuit (related appellate litigation tracked) | W38: https://law.justia.com/cases/federal/district-courts/illinois/ilndce/1%3A2024cv12935/469834/73/ | X38: Direct enforcement | Y38: Yes | Z38: Separate HCSC/BCBS Illinois case from the related BCBS Texas case. | AA38: 46295
A39: NSA-038 | B39: SpecialtyCare, Inc. et al. v. Health Care Service Corp. d/b/a BCBS Texas | C39: SpecialtyCare, Inc. / Remote Neuromonitoring Physicians / Sentient Physicians | D39: Health Care Service Corp. d/b/a BCBS Texas | E39: U.S. District Court, Northern District of Illinois | F39: Federal District | G39: 7th | H39: 1:24-cv-12945 | I39: 46175 | J39: IL | K39: TX | L39: Negative | M39: =IF(L39="Positive",1,IF(L39="Negative",-1,0)) | N39: Federal claims dismissed | O39: No | P39: No | Q39: No | S39: Dismissed federal NSA/FAA enforcement theories; state claims dismissed without prejudice. | T39: District court | U39: Final district ruling | V39: Appeal docketed in Seventh Circuit | W39: https://law.justia.com/cases/federal/district-courts/illinois/ilndce/1%3A2024cv12945/469844/73/ | X39: Direct enforcement | Y39: Yes | Z39: Court State is Illinois; Plan/Origin State is Texas. | AA39: 46295
A40: NSA-039 | B40: PHI Health, LLC v. Health Care Service Corp. d/b/a Blue Cross Blue Shield of Texas | C40: PHI Health, LLC | D40: Health Care Service Corp. d/b/a BCBS Texas | E40: U.S. District Court, Northern District of Illinois | F40: Federal District | G40: 7th | H40: 1:25-cv-12406 | I40: 46196 | J40: IL | K40: TX | L40: Negative | M40: =IF(L40="Positive",1,IF(L40="Negative",-1,0)) | N40: Enforcement claims dismissed | O40: No | P40: No | Q40: No | S40: Rejected NSA private right, FAA confirmation, and related declaratory/state consumer-fraud theories seeking payment of IDR awards. | T40: District court | U40: Final district ruling | V40: Appeal filed in 2026 | W40: https://law.justia.com/cases/federal/district-courts/illinois/ilndce/1%3A2025cv12406/487898/62/ | X40: Direct enforcement | Y40: Yes | Z40: Court State is Illinois; underlying BCBS market is Texas. | AA40: 46295
...

Sheet Dashboard Summary
A1: NSA Enforcement Litigation Dashboard - Decision Summary
A2: As of | B2: 46295
A4: Recommended heat-map universe | B4: =COUNTIF('NSA Enforcement Decisions'!Y:Y,"Yes")
A5: Positive decisions | B5: =COUNTIFS('NSA Enforcement Decisions'!L:L,"Positive",'NSA Enforcement Decisions'!Y:Y,"Yes")
A6: Negative decisions | B6: =COUNTIFS('NSA Enforcement Decisions'!L:L,"Negative",'NSA Enforcement Decisions'!Y:Y,"Yes")
A7: Nonfinal/context rows excluded | B7: =COUNTIF('NSA Enforcement Decisions'!Y:Y,"No")
A9: State | B9: Positive | C9: Negative | D9: Net Heat Score | E9: Total Included | F9: Use
A10: AZ | B10: =COUNTIFS('NSA Enforcement Decisions'!J:J,A10,'NSA Enforcement Decisions'!L:L,"Positive",'NSA Enforcement Decisions'!Y:Y,"Yes") | C10: =COUNTIFS('NSA Enforcement Decisions'!J:J,A10,'NSA Enforcement Decisions'!L:L,"Negative",'NSA Enforcement Decisions'!Y:Y,"Yes") | D10: =B10-C10 | E10: =B10+C10 | F10: Court State
A11: CA | B11: =COUNTIFS('NSA Enforcement Decisions'!J:J,A11,'NSA Enforcement Decisions'!L:L,"Positive",'NSA Enforcement Decisions'!Y:Y,"Yes") | C11: =COUNTIFS('NSA Enforcement Decisions'!J:J,A11,'NSA Enforcement Decisions'!L:L,"Negative",'NSA Enforcement Decisions'!Y:Y,"Yes") | D11: =B11-C11 | E11: =B11+C11 | F11: Court State
A12: CT | B12: =COUNTIFS('NSA Enforcement Decisions'!J:J,A12,'NSA Enforcement Decisions'!L:L,"Positive",'NSA Enforcement Decisions'!Y:Y,"Yes") | C12: =COUNTIFS('NSA Enforcement Decisions'!J:J,A12,'NSA Enforcement Decisions'!L:L,"Negative",'NSA Enforcement Decisions'!Y:Y,"Yes") | D12: =B12-C12 | E12: =B12+C12 | F12: Court State
A13: DE | B13: =COUNTIFS('NSA Enforcement Decisions'!J:J,A13,'NSA Enforcement Decisions'!L:L,"Positive",'NSA Enforcement Decisions'!Y:Y,"Yes") | C13: =COUNTIFS('NSA Enforcement Decisions'!J:J,A13,'NSA Enforcement Decisions'!L:L,"Negative",'NSA Enforcement Decisions'!Y:Y,"Yes") | D13: =B13-C13 | E13: =B13+C13 | F13: Court State
A14: FL | B14: =COUNTIFS('NSA Enforcement Decisions'!J:J,A14,'NSA Enforcement Decisions'!L:L,"Positive",'NSA Enforcement Decisions'!Y:Y,"Yes") | C14: =COUNTIFS('NSA Enforcement Decisions'!J:J,A14,'NSA Enforcement Decisions'!L:L,"Negative",'NSA Enforcement Decisions'!Y:Y,"Yes") | D14: =B14-C14 | E14: =B14+C14 | F14: Court State
A15: GA | B15: =COUNTIFS('NSA Enforcement Decisions'!J:J,A15,'NSA Enforcement Decisions'!L:L,"Positive",'NSA Enforcement Decisions'!Y:Y,"Yes") | C15: =COUNTIFS('NSA Enforcement Decisions'!J:J,A15,'NSA Enforcement Decisions'!L:L,"Negative",'NSA Enforcement Decisions'!Y:Y,"Yes") | D15: =B15-C15 | E15: =B15+C15 | F15: Court State
A16: IL | B16: =COUNTIFS('NSA Enforcement Decisions'!J:J,A16,'NSA Enforcement Decisions'!L:L,"Positive",'NSA Enforcement Decisions'!Y:Y,"Yes") | C16: =COUNTIFS('NSA Enforcement Decisions'!J:J,A16,'NSA Enforcement Decisions'!L:L,"Negative",'NSA Enforcement Decisions'!Y:Y,"Yes") | D16: =B16-C16 | E16: =B16+C16 | F16: Court State
A17: LA | B17: =COUNTIFS('NSA Enforcement Decisions'!J:J,A17,'NSA Enforcement Decisions'!L:L,"Positive",'NSA Enforcement Decisions'!Y:Y,"Yes") | C17: =COUNTIFS('NSA Enforcement Decisions'!J:J,A17,'NSA Enforcement Decisions'!L:L,"Negative",'NSA Enforcement Decisions'!Y:Y,"Yes") | D17: =B17-C17 | E17: =B17+C17 | F17: Court State
A18: MD | B18: =COUNTIFS('NSA Enforcement Decisions'!J:J,A18,'NSA Enforcement Decisions'!L:L,"Positive",'NSA Enforcement Decisions'!Y:Y,"Yes") | C18: =COUNTIFS('NSA Enforcement Decisions'!J:J,A18,'NSA Enforcement Decisions'!L:L,"Negative",'NSA Enforcement Decisions'!Y:Y,"Yes") | D18: =B18-C18 | E18: =B18+C18 | F18: Court State
A19: NJ | B19: =COUNTIFS('NSA Enforcement Decisions'!J:J,A19,'NSA Enforcement Decisions'!L:L,"Positive",'NSA Enforcement Decisions'!Y:Y,"Yes") | C19: =COUNTIFS('NSA Enforcement Decisions'!J:J,A19,'NSA Enforcement Decisions'!L:L,"Negative",'NSA Enforcement Decisions'!Y:Y,"Yes") | D19: =B19-C19 | E19: =B19+C19 | F19: Court State
A20: NY | B20: =COUNTIFS('NSA Enforcement Decisions'!J:J,A20,'NSA Enforcement Decisions'!L:L,"Positive",'NSA Enforcement Decisions'!Y:Y,"Yes") | C20: =COUNTIFS('NSA Enforcement Decisions'!J:J,A20,'NSA Enforcement Decisions'!L:L,"Negative",'NSA Enforcement Decisions'!Y:Y,"Yes") | D20: =B20-C20 | E20: =B20+C20 | F20: Court State
A21: OH | B21: =COUNTIFS('NSA Enforcement Decisions'!J:J,A21,'NSA Enforcement Decisions'!L:L,"Positive",'NSA Enforcement Decisions'!Y:Y,"Yes") | C21: =COUNTIFS('NSA Enforcement Decisions'!J:J,A21,'NSA Enforcement Decisions'!L:L,"Negative",'NSA Enforcement Decisions'!Y:Y,"Yes") | D21: =B21-C21 | E21: =B21+C21 | F21: Court State
... A23: TX | B23: =COUNTIFS('NSA Enforcement Decisions'!J:J,A23,'NSA Enforcement Decisions'!L:L,"Positive",'NSA Enforcement Decisions'!Y:Y,"Yes") | C23: =COUNTIFS('NSA Enforcement Decisions'!J:J,A23,'NSA Enforcement Decisions'!L:L,"Negative",'NSA Enforcement Decisions'!Y:Y,"Yes") | D23: =B23-C23 | E23: =B23+C23 | F23: Court State

Sheet Methodology & Coding
A1: Methodology and Dashboard Coding
A3: Field / Rule | B3: Definition
A4: Scope | B4: Publicly identifiable judicial decisions through September 29, 2026 that directly address whether/how an NSA IDR award may be confirmed, enforced, or converted to judgment. A small number of context-only confirmation/vacatur or nonfinal R&R rows are retained but flagged out of the recommended heat-map universe.
A5: Positive | B5: A court allowed a provider enforcement route to proceed or actually confirmed/enforced an NSA IDR award. Interlocutory denials of dismissal are coded positive because they recognize an enforcement route, but Decision Status identifies that they are not final judgments.
A6: Negative | B6: A court rejected the provider's enforcement/confirmation theory, dismissed the enforcement action, or affirmed such a dismissal.
A7: Heat Map Include | B7: Recommended Yes for judicial rulings that directly resolve or materially recognize/reject an enforcement route. No for nonfinal magistrate R&Rs and vacatur-only/context rows that could distort the heat map.
A8: Court State vs. Origin / Plan State | B8: Court State is the location used by the summary formulas. For federal appellate decisions, Origin / Plan State may be more intuitive for a U.S. state heat map. Your analyst can choose either field. Fifth Circuit is listed with court seat LA and origin TX.
A9: Decision counting | B9: The workbook records one row per judicial decision event, so the same litigation can appear at district and appellate levels. For a heat map of current controlling law, filter Precedential Weight to appellate authority; for a history-of-decisions map, retain all included rows.
A10: Award Amount | B10: Only populated when a reliable public source provided an amount. Some entries are approximate or aggregate and are noted in Dashboard Caution / Notes.
A11: Limitations | B11: This is a best-available public-source litigation research dataset, not a PACER-complete docket census. Sealed orders, unpublished minute orders, newly filed decisions, or decisions not indexed by public search may not appear. Rows with source limitations are specifically flagged.
A12: Update recommendation | B12: Refresh the list before each dashboard publication because appeals are active in the Second, Third, and Seventh Circuits and recent district decisions may be superseded or reversed.
A14: Scope note — REACH Air Medical v. Kaiser | B14: Excluded from enforcement decision universe | C14: The provider lost the underlying IDR and sued to vacate the award; the Eleventh Circuit affirmed dismissal on Nov. 19, 2025. It is a vacatur challenge, not an action to enforce an unpaid favorable provider IDR award. | D14: https://law.justia.com/cases/federal/appellate-courts/ca11/24-10135/24-10135-2025-11-19.html
A15: Update 2026-10-16 | B15: Added NSA-048 and NSA-053 to NSA-060 and four pending appeals approved in an internal review of 2026-10-12; updated NSA-019, NSA-026, NSA-027, NSA-035 and NSA-041. Items still under review are in an internal file.

Sheet Source Index
A1: Decision ID | B1: Case Name | C1: Decision Date | D1: Outcome | E1: Source URL | F1: Source Note
A2: NSA-001 | B2: GPS of New Jersey M.D., P.C. a/s/o *** v. Horizon Blue Cross Blue Shield of New Jersey | C2: 45177 | D2: Positive | E2: https://law.justia.com/cases/federal/district-courts/new-jersey/njdce/2%3A2022cv06614/504421/21/ | F2: Award favored payer; useful confirmation precedent but not a provider nonpayment enforcement suit.
A3: NSA-002 | B3: Worldwide Aircraft Services, Inc. d/b/a Jet ICU v. Worldwide Insurance Services, LLC d/b/a GeoBlue | C3: 45553 | D3: Positive | E3: https://docs.justia.com/cases/federal/district-courts/florida/flmdce/8%3A2024cv00840/426099/25 | F3: Positive result, but limited because the payer's challenge to FAA confirmation was treated as waived.
A4: NSA-003 | B4: FHMC LLC v. Blue Cross and Blue Shield of Arizona, Inc. | C4: 45386 | D4: Negative | E4: https://dockets.justia.com/docket/arizona/azdce/2%3A2023cv00876/1334867 | F4: Early negative enforcement decision frequently cited by later courts.
A5: NSA-004 | B5: Guardian Flight, L.L.C. v. Health Care Service Corp. | C5: 45442 | D5: Negative | E5: https://www.americanbar.org/groups/tort_trial_insurance_practice/resources/journal/2025-fall/recent-developments-health-insurance-life-insurance-disability-insurance-law/ | F5: Superseded in precedential significance by Fifth Circuit affirmance; retain as separate decision event.
A6: NSA-005 | B6: Guardian Flight, L.L.C. v. Health Care Service Corp. | C6: 45820 | D6: Negative | E6: https://www.americanbar.org/groups/health_law/news/2025/08/fifth-circuit-no-surprises-act-private-lawsuits-idr-awards/ | F6: For geographic heat map, Court State is LA (Fifth Circuit seat); Origin State is TX and may be preferable for state shading.
A7: NSA-006 | B7: Jeffrey Farkas, M.D., LLC v. Horizon Blue Cross Blue Shield of New Jersey | C7: 45840 | D7: Negative | E7: https://caselaw.findlaw.com/court/us-dis-crt-ed-new-yor/117456844.html | F7: Negative district authority in Second Circuit before East Coast appellate ruling.
A8: NSA-007 | B8: East Coast Advanced Plastic Surgery, LLC v. Cigna Health and Life Insurance Co. | C8: 45883 | D8: Negative | E8: https://law.justia.com/cases/federal/district-courts/new-york/nysdce/1%3A2025cv00255/634810/49/ | F8: Superseded in precedential significance by Second Circuit affirmance; amount is described as more than $3 million, so recorded as approximate floor.
A9: NSA-008 | B9: Modern Orthopaedics of NJ v. Premera Blue Cross | C9: 45964 | D9: Negative | E9: https://law.justia.com/cases/federal/district-courts/new-jersey/njdce/2%3A2025cv01087/562531/29/ | F9: Leading D.N.J. decision cited by many subsequent cases.
A10: NSA-009 | B10: PHI Health, LLC v. Keating Auto Group Employee Benefit Plan Trust / Entrust, LLC | C10: 46002 | D10: Negative | E10: https://www.ded.uscourts.gov/sites/ded/files/opinions/24-1378.pdf | F10: Primary public link is a later court opinion citing the adopted Texas decision (2025 WL 3617339); verify PACER citation if displaying document link publicly.
A11: NSA-010 | B11: Freeman Pain Institute, P.A. v. Horizon Blue Cross Blue Shield of New Jersey | C11: 45985 | D11: Negative | E11: https://law.justia.com/cases/federal/district-courts/new-jersey/njdce/2%3A2025cv02507/565759/20/ | F11: Part of a series of D.N.J. Horizon enforcement decisions.
A12: NSA-011 | B12: Northeast Neurosurgical Associates v. Horizon Blue Cross Blue Shield of New Jersey | C12: 45986 | D12: Negative | E12: https://law.justia.com/cases/federal/district-courts/new-jersey/njdce/2%3A2025cv06288/571096/17/ | F12: Part of a series of D.N.J. Horizon enforcement decisions.
A13: NSA-012 | B13: Garden State Pain Management v. Horizon Blue Cross Blue Shield of New Jersey | C13: 45992 | D13: Negative | E13: https://law.justia.com/cases/federal/district-courts/new-jersey/njdce/2%3A2025cv05679/570355/21/ | F13: Part of a series of D.N.J. Horizon enforcement decisions.
... A57: NSA-060 | B57: Jeffrey Farkas, M.D., LLC v. Aetna Life Insurance Company | C57: 46267 | D57: Negative | E57: https://storage.courtlistener.com/recap/gov.uscourts.nyed.549569/gov.uscourts.nyed.549569.14.0.pdf | F57: Added 2026-10-16 from an internal review of 2026-10-12.

Sheet Pending Cases
A1: Case Name | B1: Provider / Claimant | C1: Payor / Defendant | D1: Court | E1: Court Level | F1: Circuit | G1: Court State | H1: Date Filed | I1: Docket No. | J1: Status | K1: Source URL
A2: Advanced Monitoring Services Holdings, LLC v. Blue Cross Blue Shield of Oklahoma | B2: Advanced Monitoring Services Holdings, LLC | C2: Blue Cross Blue Shield of Oklahoma | D2: U.S. District Court for the Northern District of Oklahoma | E2: Federal District | F2: 10th | G2: OK | H2: 45902 | I2: 4:2025cv00466 | J2: Pending — magistrate R&R dated May 14, 2026 recommends dismissal; no final district-court disposition located through 9/30/2026. | K2: https://dockets.justia.com/docket/oklahoma/okndce/4%3A2025cv00466/74048
A3: North American Spine and Pain Institute v. Aetna Life Insurance Company | B3: North American Spine and Pain Institute | C3: Aetna Life Insurance Company | D3: U.S. District Court for the District of New Jersey | E3: Federal District | F3: 3d | G3: NJ | H3: 46083 | I3: 2:2026cv02175 | J3: Pending — stayed and administratively terminated pending related-provider lead-case proceedings. | K3: https://dockets.justia.com/docket/new-jersey/njdce/2%3A2026cv02175/592707
A4: Agag v. Cigna Health and Life Insurance Company | B4: Richard Agag, MD | C4: Cigna Health and Life Insurance Company | D4: U.S. Court of Appeals for the Second Circuit | E4: Federal Appellate | F4: 2d | G4: CT | H4: 46148 | I4: 26-1241 | J4: Appeal pending — appeal from D. Conn. enforcement ruling. | K4: https://dockets.justia.com/docket/circuit-courts/ca2/26-1241
A5: SpecialtyCare, Inc. et al. v. Health Care Service Corporation d/b/a Blue Cross Blue Shield of New Mexico | B5: SpecialtyCare, Inc.; Remote Neuromonitoring Physicians, PC; Sentient Physicians, PC | C5: Health Care Service Corporation d/b/a Blue Cross Blue Shield of New Mexico | D5: U.S. Court of Appeals for the Seventh Circuit | E5: Federal Appellate | F5: 7th | G5: IL | H5: 46185 | I5: 26-2269 | J5: Appeal pending — consolidated for briefing and disposition with related HCSC enforcement appeals. | K5: https://dockets.justia.com/docket/circuit-courts/ca7/26-2269
A6: SpecialtyCare, Inc. et al. v. Health Care Service Corporation d/b/a Blue Cross Blue Shield of Illinois | B6: SpecialtyCare, Inc.; Remote Neuromonitoring Physicians, PC; Sentient Physicians, PC | C6: Health Care Service Corporation d/b/a Blue Cross Blue Shield of Illinois | D6: U.S. Court of Appeals for the Seventh Circuit | E6: Federal Appellate | F6: 7th | G6: IL | H6: 46188 | I6: 26-2279 | J6: Appeal pending — consolidated for briefing and disposition with related HCSC enforcement appeals. | K6: https://dockets.justia.com/docket/circuit-courts/ca7/26-2279
A7: SpecialtyCare, Inc. et al. v. Health Care Service Corporation d/b/a Blue Cross Blue Shield of Texas | B7: SpecialtyCare, Inc.; Remote Neuromonitoring Physicians, PC; Sentient Physicians, PC | C7: Health Care Service Corporation d/b/a Blue Cross Blue Shield of Texas | D7: U.S. Court of Appeals for the Seventh Circuit | E7: Federal Appellate | F7: 7th | G7: IL | H7: 46188 | I7: 26-2280 | J7: Appeal pending — consolidated for briefing and disposition with related HCSC enforcement appeals. | K7: https://dockets.justia.com/docket/circuit-courts/ca7/26-2280
A8: North American Spine and Pain Institute v. Aetna Life Insurance Company | B8: North American Spine and Pain Institute | C8: Aetna Life Insurance Company | D8: U.S. District Court for the District of New Jersey | E8: Federal District | F8: 3d | G8: NJ | H8: 46204 | I8: 2:2026cv08006 | J8: Pending — removed from New Jersey Superior Court; no merits disposition located through 9/30/2026. | K8: https://dockets.justia.com/docket/new-jersey/njdce/2%3A2026cv08006/602127
A9: PHI Health, LLC v. Health Care Service Corporation d/b/a Blue Cross Blue Shield of Texas | B9: PHI Health, LLC | C9: Health Care Service Corporation d/b/a Blue Cross Blue Shield of Texas | D9: U.S. Court of Appeals for the Seventh Circuit | E9: Federal Appellate | F9: 7th | G9: IL | H9: 46205 | I9: 26-2401 | J9: Appeal pending — consolidated with related HCSC enforcement appeals; briefing ongoing. | K9: https://dockets.justia.com/docket/circuit-courts/ca7/26-2401
A10: Shareef Jandali Plastic Surgery, LLC v. Cigna Health and Life Insurance Company | B10: Shareef Jandali Plastic Surgery, LLC | C10: Cigna Health and Life Insurance Company | D10: U.S. Court of Appeals for the Second Circuit | E10: Federal Appellate | F10: 2d | G10: CT | H10: 46248 | I10: 26-2287 | J10: Appeal pending — Cigna appeal from D. Conn. judgment confirming NSA IDR award. | K10: https://dockets.justia.com/docket/circuit-courts/ca2/26-2287
A11: Shareef Jandali Plastic Surgery, LLC v. Cigna Health and Life Insurance Company | B11: Shareef Jandali Plastic Surgery, LLC | C11: Cigna Health and Life Insurance Company | D11: U.S. Court of Appeals for the Second Circuit | E11: Federal Appellate | F11: 2d | G11: CT | H11: 46251 | I11: 26-2291 | J11: Related appeal pending from the same D. Conn. enforcement judgment. | K11: https://dockets.justia.com/docket/circuit-courts/ca2/26-2291
A12: PHI Health, LLC v. Health Care Services Corp. | B12: PHI Health, LLC | C12: Health Care Services Corp. d/b/a Blue Cross Blue Shield | D12: U.S. Court of Appeals for the Seventh Circuit | E12: Federal Appellate | F12: 7th | G12: IL | H12: 46258 | I12: 26-2736 | J12: Appeal pending — consolidated with related HCSC enforcement appeals by order dated August 27, 2026. | K12: https://dockets.justia.com/docket/circuit-courts/ca7/26-2736
A13: SpecialtyCare, Inc. v. Kaiser Foundation Health Plan, Inc. (appeal of NSA-041) | B13: SpecialtyCare, Inc. | C13: Kaiser Foundation Health Plan, Inc. | D13: U.S. Court of Appeals for the Ninth Circuit | E13: Federal Appellate | F13: 9th | G13: CA | H13: 46225 | J13: Appeal pending — providers' appeal from N.D. Cal. dismissal (NSA-041); appeal docket number not yet confirmed. | K13: https://www.courtlistener.com/docket/69494254/specialtycare-inc-v-kaiser-foundation-health-plan-inc/
A14: Worldwide Aircraft Services, Inc. d/b/a Jet ICU v. Freedom Life Insurance Co. (appeal of NSA-019) | B14: Jet ICU | C14: Freedom Life Insurance Co. | D14: U.S. Court of Appeals for the Eleventh Circuit | E14: Federal Appellate | F14: 11th | G14: FL | H14: 46027 | J14: Appeal pending — provider's appeal from M.D. Fla. dismissal (NSA-019); district case stayed; appeal docket number not yet confirmed. | K14: https://www.courtlistener.com/docket/70160339/worldwide-aircraft-services-inc-v-freedom-life-insurance-company-of/
A15: Worldwide Aircraft Services, Inc. v. Aetna Life Insurance Company (appeal of NSA-053) | B15: Jet ICU | C15: Aetna Life Insurance Company | D15: U.S. Court of Appeals for the Eleventh Circuit | E15: Federal Appellate | F15: 11th | G15: FL | H15: 45910 | J15: Appeal pending — provider's appeal from M.D. Fla. dismissal (NSA-053); appeal docket number not yet confirmed. | K15: https://www.courtlistener.com/docket/70253986/worldwide-aircraft-services-inc-v-aetna-life-insurance-company/
A16: SpecialtyCare, Inc. et al. v. Aetna, Inc. (appeal of NSA-055) | B16: SpecialtyCare, Inc. | C16: Aetna, Inc. | D16: U.S. Court of Appeals for the Third Circuit | E16: Federal Appellate | F16: 3d | G16: PA | H16: 46042 | J16: Appeal pending — providers' appeal from M.D. Pa. judgment on the pleadings (NSA-055); appeal docket number not yet confirmed. | K16: https://www.courtlistener.com/docket/70294954/specialtycare-inc-v-aetna-inc/

Sheet DOL Actions
A1: Title | B1: Agency | C1: Type | D1: Date Issued | E1: Effective Date | F1: Status | G1: Summary | H1: Source URL
A2: Requirements Related to Surprise Billing; Part I | B2: DOL / HHS / Treasury / OPM | C2: Rule | D2: 44390 | E2: 44452 | F2: Partially superseded / finalized by later rules | G2: Interim final rule implementing major NSA protections and the QPA framework that later became central to IDR litigation. | H2: https://regulations.justia.com/regulations/fedreg/2021/07/13/2021-14379.html
A3: Requirements Related to Surprise Billing; Part II | B3: DOL / HHS / Treasury / OPM | C3: Rule | D3: 44476 | E3: 44476 | F3: Portions vacated; later provisions finalized/revised | G3: Interim final rule establishing the federal IDR process and directing certified IDR entities how to consider the QPA and additional statutory factors. | H3: https://www.dol.gov/resource-library/requirements-related-surprise-billing-part-ii
A4: Texas Medical Association v. HHS (TMA I) | B4: U.S. District Court, E.D. Texas | C4: Court Action | D4: 44615 | E4: 44615 | F4: Portions of 2021 IDR rule vacated | G4: Court vacated provisions that effectively gave the QPA presumptive or preferred weight in IDR payment determinations and found the rule inconsistent with the statute. | H4: https://law.justia.com/cases/federal/district-courts/texas/txedce/6%3A2021cv00425/211847/113/
A5: LifeNet, Inc. v. HHS | B5: U.S. District Court, E.D. Texas | C5: Court Action | D5: 44768 | E5: 44768 | F5: Air-ambulance IDR provisions vacated | G5: Court applied the TMA reasoning to air-ambulance IDR and vacated parallel provisions that improperly constrained consideration of statutory factors. | H5: https://law.justia.com/cases/federal/district-courts/texas/txedce/6%3A2022cv00162/214240/40/
A6: Requirements Related to Surprise Billing — Final Rules | B6: DOL / HHS / Treasury | C6: Rule | D6: 44799 | E6: 44859 | F6: Partially vacated by TMA II; remaining provisions operative unless superseded | G6: Final rule revised QPA disclosures and IDR decision standards after TMA I/LifeNet; required consideration of QPA and credible additional information without the earlier explicit presumption. | H6: https://www.govinfo.gov/content/pkg/FR-2022-08-26/pdf/FR-2022-08-26.pdf
A7: Texas Medical Association v. HHS (TMA II) | B7: U.S. District Court, E.D. Texas | C7: Court Action | D7: 44963 | E7: 44963 | F7: Challenged portions of 2022 final rule vacated | G7: Court held that the 2022 rule still impermissibly restricted the arbitrator’s consideration of statutory factors and vacated challenged provisions. | H7: https://law.justia.com/cases/federal/district-courts/texas/txedce/6%3A2022cv00372/217452/99/
A8: Texas Medical Association v. HHS (TMA IV) | B8: U.S. District Court, E.D. Texas | C8: Court Action | D8: 45141 | E8: 45141 | F8: Administrative-fee and batching guidance vacated | G8: Court vacated the 2023 $350 administrative-fee increase and challenged batching restrictions for failure to use notice-and-comment rulemaking. | H8: https://law.justia.com/cases/federal/district-courts/texas/txedce/6%3A2023cv00059/219983/50/
